Exception in Tkinter callback
Traceback (most recent call last):
  File "C:\Users\NghiaDo\AppData\Local\Programs\Python\Python311\Lib\tkinter\__init__.py", line 1948, in __call__
    return self.func(*args)
           ^^^^^^^^^^^^^^^^
  File "C:\Users\NghiaDo\device.py", line 10, in get_device_info
    output = subprocess.run(["adb", "shell", "getprop"], capture_output=True, text=True).stdout
             ^^^^^^^^^^^^^^
AttributeError: module 'subprocess' has no attribute 'run'